Workbook
Name budget: [1]Decision_table!$S$2
Name max_comm: People!$N$26
Name max_graz: People!$AN$26
Name max_hunt: People!$AA$26
Name max_native: native_rareplants!$AR$54
Name max_rare: native_rareplants!$AR$28
Name num_choices: [1]Decision_table!$R$9:$R$30

Sheet paddock_data
F1: COST | R1: FIRE RISK | AD1: Rare and endangered benefits | AV1: Native forest cover | BC1: Community | BO1: Hunters | CA1: Grazing
B2: Area | C2: elevation | D2: Paddock size (m2) | E2: Management Unit | F2: Alt_1 | G2: Alt_2 | H2: Alt_3 | I2: Alt_4 | J2: Alt_5 | K2: Alt_6 | L2: Alt_7 | M2: Alt_8 | N2: Alt_9 | O2: Alt_10 | P2: Alt_11 | R2: Alt_1 | S2: Alt_2 | T2: Alt_3 | U2: Alt_4 | V2: Alt_5 | W2: Alt_6 | X2: Alt_7 | Y2: Alt_8 | Z2: Alt_9 | AA2: Alt_10 | AB2: Alt_11 | AD2: Alt_1 | AE2: Alt_2 | AF2: Alt_3 | AG2: Alt_4 | AH2: Alt_5 | AI2: Alt_6 | AJ2: Alt_7 | AK2: Alt_8 | AL2: Alt_9 | AM2: Alt_10 | AN2: Alt_11 | AQ2: Alt_1 | AR2: Alt_2 | AS2: Alt_3 | AT2: Alt_4 | AU2: Alt_5 | AV2: Alt_6 | AW2: Alt_7 | AX2: Alt_8 | AY2: Alt_9 | AZ2: Alt_10 | BA2: Alt_11 | BC2: Alt_1 | BD2: Alt_2 | BE2: Alt_3 | BF2: Alt_4 | BG2: Alt_5 | BH2: Alt_6 | BI2: Alt_7 | BJ2: Alt_8 | BK2: Alt_9 | BL2: Alt_10 | BM2: Alt_11 | BO2: Alt_1 | BP2: Alt_2 | BQ2: Alt_3 | BR2: Alt_4 | BS2: Alt_5 | BT2: Alt_6 | BU2: Alt_7 | BV2: Alt_8 | BW2: Alt_9 | BX2: Alt_10 | BY2: Alt_11 | CA2: Alt_1 | CB2: Alt_2 | CC2: Alt_3 | CD2: Alt_4 | CE2: Alt_5 | CF2: Alt_6 | CG2: Alt_7 | CH2: Alt_8 | CI2: Alt_9 | CJ2: Alt_10 | CK2: Alt_11
B3: Puu Waawaa | C3: Makai | D3: 488554 | E3: 1 | F3: 802403.5 | G3: =(D3/D$27)*G$27 -> 1686.8636 | H3: 945878.42 | I3: 802403.5 | J3: 1291900.1 | K3: 1291900.1 | L3: 1994685 | M3: 802403.5 | N3: 802403.5 | O3: 578767.95 | P3: 0 | R3: 0.52966491 | S3: 0.21186596 | T3: 0.52966491 | U3: 0.52966491 | V3: 0.52966491 | W3: 0.52966491 | X3: 0.60123687 | Y3: 0.52966491 | Z3: 0.52966491 | AA3: 0 | AB3: 0 | AD3: 0 | AE3: 0 | AF3: 0 | AG3: 0 | AH3: 0 | AI3: 0 | AJ3: 0 | AK3: 0 | AL3: 0 | AM3: 0 | AN3: 0 | AQ3: 0.0036574588 | AR3: 0.0025286094 | AS3: 0.0018814155 | AT3: 0.0045454804 | AU3: 0.0045454804 | AV3: 0.005433502 | AW3: 0.0083517966 | AX3: 0.004440108 | AY3: 0.0072095452 | AZ3: 0.004440108 | BA3: 0.0017760432 | BC3: 3 | BD3: 9 | BE3: 9 | BF3: 3 | BG3: 3 | BH3: 3 | BI3: 9 | BJ3: 3 | BK3: 3 | BL3: 6 | BM3: 0 | BO3: 1 | BP3: 1 | BQ3: 1 | BR3: -2 | BS3: -4 | BT3: -4 | BU3: -4 | BV3: 1 | BW3: -3 | BX3: 2 | BY3: 0 | CA3: 3 | CB3: 1 | CC3: 4 | CD3: -4 | CE3: -4 | CF3: -4 | CG3: -4 | CH3: 1 | CI3: -4 | CJ3: 2 | CK3: 0
B4: Puu Waawaa | C4: Makai | D4: 564453 | E4: 2 | F4: 585346.4 | G4: =(D4/D$27)*G$27 -> 1948.9253 | H4: 702251.94 | I4: 585346.4 | J4: 953029.72 | K4: 953937.33 | L4: 1765903 | M4: 586254.01 | N4: 586254.01 | O4: 478274.74 | P4: 0 | R4: 0.79747096 | S4: 0.31898838 | T4: 0.79747096 | U4: 0.79747096 | V4: 0.79747096 | W4: 0.79747095 | X4: 1 | Y4: 0.79747095 | Z4: 0.79747095 | AA4: 0 | AB4: 0 | AD4: 0.0030568155 | AE4: 0.0019295202 | AF4: 0.0018788255 | AG4: 0.0036458105 | AH4: 0.0036458105 | AI4: 0.0042348055 | AJ4: 0.0064789447 | AK4: 0.0029449749 | AL4: 0.0054127954 | AM4: 0.0029449749 | AN4: 0.00117799 | AQ4: 0.0013281637 | AR4: 0.0008383622 | AS4: 0.00081633576 | AT4: 0.0015840776 | AU4: 0.0015840776 | AV4: 0.0018399915 | AW4: 0.0028150534 | AX4: 0.0012795697 | AY4: 0.0023518194 | AZ4: 0.0012795697 | BA4: 0.00051182789 | BC4: 3 | BD4: 9 | BE4: 9 | BF4: 3 | BG4: 3 | BH4: 3 | BI4: 9 | BJ4: 3 | BK4: 3 | BL4: 6 | BM4: 0 | BO4: 1 | BP4: 1 | BQ4: 1 | BR4: -2 | BS4: -4 | BT4: -4 | BU4: -4 | BV4: 1 | BW4: -3 | BX4: 2 | BY4: 0 | CA4: 3 | CB4: 1 | CC4: 4 | CD4: -4 | CE4: -4 | CF4: -4 | CG4: -4 | CH4: 1 | CI4: -4 | CJ4: 2 | CK4: 0
B5: Puu Waawaa | C5: Makai | D5: 804948 | E5: 3 | F5: 543880.34 | G5: =(D5/D$27)*G$27 -> 2779.2987 | H5: 655710.13 | I5: 543880.34 | J5: 888292.75 | K5: 890642.26 | L5: 2048560 | M5: 546229.85 | N5: 546229.85 | O5: 522558.88 | P5: 0 | R5: 0.49385319 | S5: 0.19754128 | T5: 0.49385319 | U5: 0.49385319 | V5: 0.49385319 | W5: 0.49412888 | X5: 0.58139776 | Y5: 0.49412888 | Z5: 0.49412888 | AA5: 0 | AB5: 0 | AD5: 0.0070244945 | AE5: 0.0049301797 | AF5: 0.0034905246 | AG5: 0.0087914794 | AH5: 0.0087914794 | AI5: 0.010560413 | AJ5: 0.016478179 | AK5: 0.0088349247 | AL5: 0.014094383 | AM5: 0.0088349247 | AN5: 0.0035339699 | AQ5: 0.015794586 | AR5: 0.011085517 | AS5: 0.0078484498 | AT5: 0.019767655 | AU5: 0.019767655 | AV5: 0.023745104 | AW5: 0.03705121 | AX5: 0.019865341 | AY5: 0.031691241 | AZ5: 0.019865341 | BA5: 0.0079461366 | BC5: 3 | BD5: 9 | BE5: 9 | BF5: 3 | BG5: 3 | BH5: 3 | BI5: 9 | BJ5: 3 | BK5: 3 | BL5: 6 | BM5: 0 | BO5: 1 | BP5: 1 | BQ5: 1 | BR5: -2 | BS5: -4 | BT5: -4 | BU5: -4 | BV5: 1 | BW5: -3 | BX5: 2 | BY5: 0 | CA5: 3 | CB5: 1 | CC5: 4 | CD5: -4 | CE5: -4 | CF5: -4 | CG5: -4 | CH5: 1 | CI5: -4 | CJ5: 2 | CK5: 0
B6: Puu Waawaa | C6: Makai | D6: 704315 | E6: 4 | F6: 460198.98 | G6: =(D6/D$27)*G$27 -> 2431.8363 | H6: 561785.56 | I6: 460198.98 | J6: 757649.11 | K6: 759681.45 | L6: 1772838.6 | M6: 462231.32 | N6: 462231.32 | O6: 447328.78 | P6: 0 | R6: 0.33064545 | S6: 0.13225818 | T6: 0.33064545 | U6: 0.33064545 | V6: 0.33064545 | W6: 0.33064544 | X6: 0.40876937 | Y6: 0.33064544 | Z6: 0.33064544 | AA6: 0 | AB6: 0 | AD6: 0.005218624 | AE6: 0.0039722335 | AF6: 0.0020773175 | AG6: 0.0067892773 | AH6: 0.0067892773 | AI6: 0.0083599304 | AJ6: 0.013562713 | AK6: 0.0078532664 | AL6: 0.011501237 | AM6: 0.0078532664 | AN6: 0.0031413065 | AQ6: 0.0067555995 | AR6: 0.0051421254 | AS6: 0.0026891236 | AT6: 0.0087888375 | AU6: 0.0087888375 | AV6: 0.010822075 | AW6: 0.017557167 | AX6: 0.01016619 | AY6: 0.014888551 | AZ6: 0.01016619 | BA6: 0.0040664759 | BC6: 3 | BD6: 9 | BE6: 9 | BF6: 3 | BG6: 3 | BH6: 3 | BI6: 9 | BJ6: 3 | BK6: 3 | BL6: 6 | BM6: 0 | BO6: 1 | BP6: 1 | BQ6: 1 | BR6: -2 | BS6: -4 | BT6: -4 | BU6: -4 | BV6: 1 | BW6: -3 | BX6: 2 | BY6: 0 | CA6: 3 | CB6: 1 | CC6: 4 | CD6: -4 | CE6: -4 | CF6: -4 | CG6: -4 | CH6: 1 | CI6: -4 | CJ6: 2 | CK6: 0
B7: Puu Waawaa | C7: Makai | D7: 2172640 | E7: 5 | F7: 906962.98 | G7: =(D7/D$27)*G$27 -> 7501.622 | H7: 1063236.8 | I7: 906962.98 | J7: 1455138.7 | K7: 1467222.2 | L7: 4592564.8 | M7: 919046.47 | N7: 919046.47 | O7: 1110506.9 | P7: 0 | R7: 0.40267765 | S7: 0.16107106 | T7: 0.40267765 | U7: 0.40267765 | V7: 0.40267765 | W7: 0.40383331 | X7: 0.56260033 | Y7: 0.40383331 | Z7: 0.40383331 | AA7: 0 | AB7: 0 | AD7: 0.041116015 | AE7: 0.030111089 | AF7: 0.018341542 | AG7: 0.052503251 | AH7: 0.052503251 | AI7: 0.063943126 | AJ7: 0.10533651 | AK7: 0.056936181 | AL7: 0.086717598 | AM7: 0.056936181 | AN7: 0.022774472 | AQ7: 0.041341203 | AR7: 0.030276004 | AS7: 0.018441997 | AT7: 0.052790805 | AU7: 0.052790805 | AV7: 0.064293335 | AW7: 0.10591342 | AX7: 0.057248014 | AY7: 0.087192541 | AZ7: 0.057248014 | BA7: 0.022899206 | BC7: 3 | BD7: 9 | BE7: 9 | BF7: 3 | BG7: 3 | BH7: 3 | BI7: 9 | BJ7: 3 | BK7: 3 | BL7: 6 | BM7: 0 | BO7: 1 | BP7: 1 | BQ7: 1 | BR7: -2 | BS7: -4 | BT7: -4 | BU7: -4 | BV7: 1 | BW7: -3 | BX7: 2 | BY7: 0 | CA7: 3 | CB7: 1 | CC7: 4 | CD7: -4 | CE7: -4 | CF7: -4 | CG7: -4 | CH7: 1 | CI7: -4 | CJ7: 2 | CK7: 0
B8: Puu Waawaa | C8: Makai | D8: 3072920 | E8: 6 | F8: 958827.22 | G8: =(D8/D$27)*G$27 -> 10610.08 | H8: 1121449.6 | I8: 958827.22 | J8: 1536109.3 | K8: 1537234.3 | L8: 5957629.7 | M8: 959952.18 | N8: 959952.18 | O8: 1392501.9 | P8: 0 | R8: 0.6216904 | S8: 0.24867616 | T8: 0.6216904 | U8: 0.6216904 | V8: 0.6216904 | W8: 0.62174413 | X8: 0.85390778 | Y8: 0.62174413 | Z8: 0.62174413 | AA8: 0 | AB8: 0 | AD8: 0.0052853601 | AE8: 0.003527732 | AF8: 0.0029293802 | AG8: 0.00646335 | AH8: 0.00646335 | AI8: 0.0076415932 | AJ8: 0.012269509 | AK8: 0.0058899498 | AL8: 0.0099975731 | AM8: 0.0058899498 | AN8: 0.0023559799 | AQ8: 0.017521934 | AR8: 0.011695076 | AS8: 0.0097114305 | AT8: 0.021427186 | AU8: 0.021427186 | AV8: 0.025333278 | AW8: 0.040675664 | AX8: 0.01952626 | AY8: 0.033143782 | AZ8: 0.01952626 | BA8: 0.0078105039 | BC8: 3 | BD8: 9 | BE8: 9 | BF8: 3 | BG8: 3 | BH8: 3 | BI8: 9 | BJ8: 3 | BK8: 3 | BL8: 6 | BM8: 0 | BO8: 1 | BP8: 1 | BQ8: 1 | BR8: -2 | BS8: -4 | BT8: -4 | BU8: -4 | BV8: 1 | BW8: -3 | BX8: 2 | BY8: 0 | CA8: 3 | CB8: 1 | CC8: 4 | CD8: -4 | CE8: -4 | CF8: -4 | CG8: -4 | CH8: 1 | CI8: -4 | CJ8: 2 | CK8: 0
B9: Puu Waawaa | C9: Makai | D9: 2220560 | E9: 7 | F9: 915650.33 | G9: =(D9/D$27)*G$27 -> 7667.0786 | H9: 1072987.5 | I9: 915650.33 | J9: 1468701.4 | K9: 1475524.1 | L9: 4669799.7 | M9: 922472.99 | N9: 922472.99 | O9: 1128843 | P9: 0 | R9: 0.66739253 | S9: 0.26695701 | T9: 0.66739253 | U9: 0.66739253 | V9: 0.66739253 | W9: 0.6673925 | X9: 0.92400342 | Y9: 0.6673925 | Z9: 0.6673925 | AA9: 0 | AB9: 0 | AD9: 0.025669964 | AE9: 0.01686473 | AF9: 0.014675392 | AG9: 0.031167251 | AH9: 0.031167251 | AI9: 0.036664537 | AJ9: 0.058799051 | AK9: 0.027486432 | AL9: 0.04765911 | AM9: 0.027486432 | AN9: 0.010994573 | AQ9: 0.012499801 | AR9: 0.0082121563 | AS9: 0.0071460743 | AT9: 0.015176664 | AU9: 0.015176664 | AV9: 0.017853527 | AW9: 0.028631767 | AX9: 0.013384317 | AY9: 0.023207254 | AZ9: 0.013384317 | BA9: 0.0053537266 | BC9: 3 | BD9: 9 | BE9: 9 | BF9: 3 | BG9: 3 | BH9: 3 | BI9: 9 | BJ9: 3 | BK9: 3 | BL9: 6 | BM9: 0 | BO9: 1 | BP9: 1 | BQ9: 1 | BR9: -2 | BS9: -4 | BT9: -4 | BU9: -4 | BV9: 1 | BW9: -3 | BX9: 2 | BY9: 0 | CA9: 3 | CB9: 1 | CC9: 4 | CD9: -4 | CE9: -4 | CF9: -4 | CG9: -4 | CH9: 1 | CI9: -4 | CJ9: 2 | CK9: 0
B10: Puu Waawaa | C10: Makai | D10: 1492830 | E10: 8 | F10: 703316.8 | G10: =(D10/D$27)*G$27 -> 5154.3957 | H10: 834662.79 | I10: 703316.8 | J10: 1137205.5 | K10: 1177552.8 | L10: 3324988.7 | M10: 743664.02 | N10: 743664.02 | O10: 805261.26 | P10: 0 | R10: 0.52369912 | S10: 0.20947965 | T10: 0.52369912 | U10: 0.52369912 | V10: 0.52369912 | W10: 0.52537476 | X10: 0.73784156 | Y10: 0.52537476 | Z10: 0.52537476 | AA10: 0 | AB10: 0 | AD10: 0.17365065 | AE10: 0.12034943 | AF10: 0.088835371 | AG10: 0.21605829 | AH10: 0.21605829 | AI10: 0.25875016 | AJ10: 0.42201394 | AK10: 0.21203819 | AL10: 0.34356544 | AM10: 0.21203819 | AN10: 0.084815277 | AQ10: 0.0029655987 | AR10: 0.0020553226 | AS10: 0.0015171268 | AT10: 0.0036898346 | AU10: 0.0036898346 | AV10: 0.0044189248 | AW10: 0.0072071369 | AX10: 0.0036211796 | AY10: 0.0058673966 | AZ10: 0.0036211796 | BA10: 0.0014484718 | BC10: 3 | BD10: 9 | BE10: 9 | BF10: 3 | BG10: 3 | BH10: 3 | BI10: 9 | BJ10: 3 | BK10: 3 | BL10: 6 | BM10: 0 | BO10: 1 | BP10: 1 | BQ10: 1 | BR10: -2 | BS10: -4 | BT10: -4 | BU10: -4 | BV10: 1 | BW10: -3 | BX10: 2 | BY10: 0 | CA10: 3 | CB10: 1 | CC10: 4 | CD10: -4 | CE10: -4 | CF10: -4 | CG10: -4 | CH10: 1 | CI10: -4 | CJ10: 2 | CK10: 0
B11: Puu Waawaa | C11: Makai | D11: 1715970 | E11: 9 | F11: 827824.48 | G11: =(D11/D$27)*G$27 -> 5924.8464 | H11: 974411.12 | I11: 827824.48 | J11: 1331587.4 | K11: 1427781.4 | L11: 3896204.2 | M11: 924018.49 | N11: 924018.49 | O11: 937815.45 | P11: 0 | R11: 0.33127441 | S11: 0.13250977 | T11: 0.33127441 | U11: 0.33127441 | V11: 0.33127441 | W11: 0.33501021 | X11: 0.44544054 | Y11: 0.33501021 | Z11: 0.33501021 | AA11: 0 | AB11: 0 | AD11: 0.37863672 | AE11: 0.28810152 | AF11: 0.150892 | AG11: 0.49250909 | AH11: 0.49250909 | AI11: 0.60808307 | AJ11: 1 | AK11: 0.56936181 | AL11: 0.83582779 | AM11: 0.56936181 | AN11: 0.22774472 | AQ11: 0.033761037 | AR11: 0.025688492 | AS11: 0.013454243 | AT11: 0.043914434 | AU11: 0.043914434 | AV11: 0.054219556 | AW11: 0.089164719 | AX11: 0.050766986 | AY11: 0.07452635 | AZ11: 0.050766986 | BA11: 0.020306794 | BC11: 3 | BD11: 9 | BE11: 9 | BF11: 3 | BG11: 3 | BH11: 3 | BI11: 9 | BJ11: 3 | BK11: 3 | BL11: 6 | BM11: 0 | BO11: 1 | BP11: 1 | BQ11: 1 | BR11: -2 | BS11: -4 | BT11: -4 | BU11: -4 | BV11: 1 | BW11: -3 | BX11: 2 | BY11: 0 | CA11: 3 | CB11: 1 | CC11: 4 | CD11: -4 | CE11: -4 | CF11: -4 | CG11: -4 | CH11: 1 | CI11: -4 | CJ11: 2 | CK11: 0
B12: Puu Waawaa | C12: Makai | D12: 1513710 | E12: 10 | F12: 847549.75 | G12: =(D12/D$27)*G$27 -> 5226.4895 | H12: 996550.9 | I12: 847549.75 | J12: 1362382.5 | K12: 1362987.6 | L12: 3540459.5 | M12: 848154.82 | N12: 848154.82 | O12: 892070.51 | P12: 0 | R12: 0.26381935 | S12: 0.10552774 | T12: 0.26381935 | U12: 0.26381935 | V12: 0.26381935 | W12: 0.26605521 | X12: 0.34394247 | Y12: 0.26605521 | Z12: 0.26605521 | AA12: 0 | AB12: 0 | AD12: 0.0011996954 | AE12: 0.00095107413 | AF12: 0.00041436873 | AG12: 0.0015923587 | AH12: 0.0015923587 | AI12: 0.0019885338 | AJ12: 0.0032888576 | AK12: 0.0019633166 | AL12: 0.0027738604 | AM12: 0.0019633166 | AN12: 0.00078532664 | AQ12: 0.0053168454 | AR12: 0.0042149984 | AS12: 0.0018364116 | AT12: 0.0070570623 | AU12: 0.0070570623 | AV12: 0.0088128427 | AW12: 0.014575656 | AX12: 0.0087010845 | AY12: 0.012293277 | AZ12: 0.0087010845 | BA12: 0.0034804338 | BC12: 3 | BD12: 9 | BE12: 9 | BF12: 3 | BG12: 3 | BH12: 3 | BI12: 9 | BJ12: 3 | BK12: 3 | BL12: 6 | BM12: 0 | BO12: 1 | BP12: 1 | BQ12: 1 | BR12: -2 | BS12: -4 | BT12: -4 | BU12: -4 | BV12: 1 | BW12: -3 | BX12: 2 | BY12: 0 | CA12: 3 | CB12: 1 | CC12: 4 | CD12: -4 | CE12: -4 | CF12: -4 | CG12: -4 | CH12: 1 | CI12: -4 | CJ12: 2 | CK12: 0
B13: Puu Waawaa | C13: Middle | D13: 1680430 | E13: 11 | F13: 729595.18 | G13: =(D13/D$27)*G$27 -> 5802.135 | H13: 864157.83 | I13: 729595.18 | J13: 1178231.4 | K13: 1179441.6 | L13: 3596740.1 | M13: 730805.32 | N13: 730805.32 | O13: 872705.62 | P13: 0 | R13: 0.15198637 | S13: 0.06079455 | T13: 0.15198637 | U13: 0.15198637 | V13: 0.15198637 | W13: 0.15208305 | X13: 0.15534709 | Y13: 0.15208305 | Z13: 0.15208305 | AA13: 0 | AB13: 0 | AD13: 0.0020480891 | AE13: 0.0017616276 | AF13: 0.00047743579 | AG13: 0.0028334157 | AH13: 0.0028334157 | AI13: 0.003619046 | AJ13: 0.0059852793 | AK13: 0.0039266332 | AL13: 0.0051896993 | AM13: 0.0039266332 | AN13: 0.0015706533 | AQ13: 0.00032702594 | AR13: 0.00028128558 | AS13: 7.6233936e-05 | AT13: 0.00045242195 | AU13: 0.00045242195 | AV13: 0.00057786644 | AW13: 0.00095569165 | AX13: 0.00062698002 | AY13: 0.00082865845 | AZ13: 0.00062698002 | BA13: 0.00025079201 | BC13: 1 | BD13: 3 | BE13: 3 | BF13: 1 | BG13: 1 | BH13: 1 | BI13: 3 | BJ13: 1 | BK13: 1 | BL13: 2 | BM13: 0 | BO13: 2 | BP13: 2 | BQ13: 2 | BR13: -4 | BS13: -8 | BT13: -8 | BU13: -8 | BV13: 2 | BW13: -6 | BX13: 4 | BY13: 0 | CA13: 6 | CB13: 2 | CC13: 8 | CD13: -8 | CE13: -8 | CF13: -8 | CG13: -8 | CH13: 2 | CI13: -8 | CJ13: 4 | CK13: 0
B14: Puu Waawaa | C14: Middle | D14: 2169210 | E14: 12 | F14: 823798.7 | G14: =(D14/D$27)*G$27 -> 7489.779 | H14: 969892.55 | I14: 823798.7 | J14: 1325302.3 | K14: 1326785.9 | L14: 4447194.5 | M14: 825282.27 | N14: 825282.27 | O14: 1062871.3 | P14: 0 | R14: 0.27049805 | S14: 0.10819922 | T14: 0.27049805 | U14: 0.27049805 | V14: 0.27049805 | W14: 0.27052038 | X14: 0.31488215 | Y14: 0.27052038 | Z14: 0.27052038 | AA14: 0 | AB14: 0 | AD14: 0.0030254632 | AE14: 0.0023881752 | AF14: 0.0010621466 | AG14: 0.0040071215 | AH14: 0.0040071215 | AI14: 0.0049888675 | AJ14: 0.0081080348 | AK14: 0.0049082915 | AL14: 0.0069521841 | AM14: 0.0049082915 | AN14: 0.0019633166 | AQ14: 0.029447072 | AR14: 0.023244298 | AS14: 0.010337957 | AT14: 0.03900163 | AU14: 0.03900163 | AV14: 0.048557041 | AW14: 0.078916143 | AX14: 0.047772788 | AY14: 0.067666156 | AZ14: 0.047772788 | BA14: 0.019109115 | BC14: 1 | BD14: 3 | BE14: 3 | BF14: 1 | BG14: 1 | BH14: 1 | BI14: 3 | BJ14: 1 | BK14: 1 | BL14: 2 | BM14: 0 | BO14: 2 | BP14: 2 | BQ14: 2 | BR14: -4 | BS14: -8 | BT14: -8 | BU14: -8 | BV14: 2 | BW14: -6 | BX14: 4 | BY14: 0 | CA14: 6 | CB14: 2 | CC14: 8 | CD14: -8 | CE14: -8 | CF14: -8 | CG14: -8 | CH14: 2 | CI14: -8 | CJ14: 4 | CK14: 0
... B24: Puu Waawaa | C24: Mauka | D24: 3550930 | E24: 22 | F24: 652397.95 | G24: =(D24/D$27)*G$27 -> 12260.538 | H24: 1195902.2 | I24: 652397.95 | J24: 1266906.4 | K24: 1267917.2 | L24: 2315086.5 | M24: 653408.73 | N24: 653408.73 | O24: 965669.57 | P24: 0 | R24: 0.43846768 | S24: 0.17538707 | T24: 0.43846768 | U24: 0.43846768 | V24: 0.43846768 | W24: 0.43846768 | X24: 0.55906795 | Y24: 0.43846768 | Z24: 0.43846768 | AA24: 0 | AB24: 0 | AD24: 0.004422022 | AE24: 0.0031823967 | AF24: 0.0020660421 | AG24: 0.0056000119 | AH24: 0.0056000119 | AI24: 0.0067780019 | AJ24: 0.010880235 | AK24: 0.0058899498 | AL24: 0.0091339818 | AM24: 0.0058899498 | AN24: 0.0023559799 | AQ24: 0.11197554 | AR24: 0.080585442 | AS24: 0.052316832 | AT24: 0.1418049 | AU24: 0.1418049 | AV24: 0.17163425 | AW24: 0.27551203 | AX24: 0.14914677 | AY24: 0.23129296 | AZ24: 0.14914677 | BA24: 0.05965871 | BC24: 2 | BD24: 6 | BE24: 6 | BF24: 2 | BG24: 2 | BH24: 2 | BI24: 6 | BJ24: 2 | BK24: 2 | BL24: 4 | BM24: 0 | BO24: 3 | BP24: 3 | BQ24: 3 | BR24: -6 | BS24: -12 | BT24: -12 | BU24: -12 | BV24: 3 | BW24: -9 | BX24: 6 | BY24: 0 | CA24: 9 | CB24: 3 | CC24: 12 | CD24: -12 | CE24: -12 | CF24: -12 | CG24: -12 | CH24: 3 | CI24: -12 | CJ24: 6 | CK24: 0
B25: 1 | C25: 2 | D25: 3 | E25: 4 | AB25: 1 | AN25: 1 | BA25: 1 | BM25: 9 | BY25: 6 | CK25: 12
R26: **CHECK FLAMMABILITY SHEET - USE SCALED CHANGE IN FLAMMABILITY INSTEAD? | BO26: -4 | BP26: 2
D27: =SUM(D3:D24) -> 39874401 | G27: 137677.06 | BO27: -4 | BP27: 2
G28: note: single cost for roadside fuel break | BD28: Community | BE28: Hunters | BF28: Grazing | BI28: Community | BJ28: Hunters | BK28: Grazing | BO28: -4 | BP28: 2
AE29: Native | AF29: Score | BC29: Alt_1 | BD29: lo | BE29: lo | BF29: med | BH29: Makai | BI29: 3 | BJ29: 1 | BK29: 1 | BO29: -4 | BP29: 2
H30: Makai | I30: Mauka | O30: Fire Risk Effort | P30: Fire contribution score | AD30: Alt_1 | AE30: med | AF30: 3 | AJ30: Makai | AK30: 3 | AL30: Mauka road | AM30: 0 | AN30: 0 | BC30: Alt_2 | BD30: med | BE30: lo | BF30: lo | BH30: middle | BI30: 1 | BJ30: 2 | BK30: 2 | BL30: Mauka road | BM30: 9 | BN30: 0 | BO30: -4 | BP30: 2 | BX30: Mauka road | BY30: 2 | BZ30: -4 | CJ30: Mauka road | CK30: 4 | CL30: -4
G31: Alt_1 | H31: Lo | I31: Lo | K31: Lo | L31: 25 | N31: Alt_1 | O31: Low | P31: 1 | R31: Makai | S31: 2 | AD31: Alt_2 | AE31: lo | AF31: 1 | AJ31: middle | AK31: 1 | AL31: Mauka road | AM31: 0.0064789447 | AN31: 0.00117799 | BC31: Alt_3 | BD31: med | BE31: lo | BF31: hi | BH31: Mauka | BI31: 2 | BJ31: 3 | BK31: 3 | BL31: Mauka road | BM31: 9 | BN31: 0 | BO31: -4 | BP31: 2 | BX31: Mauka road | BY31: 2 | BZ31: -4 | CJ31: Mauka road | CK31: 4 | CL31: -4
G32: Alt_2 | H32: Med | I32: Med | K32: Med | L32: 55 | N32: Alt_2 | O32: high | P32: 3 | R32: middle | S32: 1 | AD32: Alt_3 | AE32: -med | AF32: -2 | AJ32: Mauka | AK32: 2 | AL32: Mauka road | AM32: 0.016478179 | AN32: 0.0034905246 | BC32: Alt_4 | BD32: lo | BE32: -lo-med | BF32: -hi | BL32: Mauka road | BM32: 9 | BN32: 0 | BO32: -4 | BP32: 2 | BX32: Mauka road | BY32: 2 | BZ32: -4 | CJ32: Mauka road | CK32: 4 | CL32: -4
G33: Alt_3 | H33: Med | I33: Med | K33: Med-Hi | L33: 70 | N33: Alt_3 | O33: high | P33: 3 | R33: Mauka | S33: 0 | AD33: Alt_4 | AE33: lo | AF33: 1 | AH33: Text | AI33: Score | AL33: Mauka road | AM33: 0.013562713 | AN33: 0.0020773175 | BC33: Alt_5 | BD33: lo | BE33: -hi | BF33: -hi | BI33: -hi | BJ33: -4 | BL33: Mauka road | BM33: 9 | BN33: 0 | BO33: -4 | BP33: 2 | BX33: Mauka road | BY33: 2 | BZ33: -4 | CJ33: Mauka road | CK33: 4 | CL33: -4
G34: Alt_4 | H34: Med | I34: Med | K34: HI | L34: 85 | N34: Alt_4 | O34: high | P34: 3 | AD34: Alt_5 | AE34: lo | AF34: 1 | AH34: -med | AI34: -2 | AL34: Mauka road | AM34: 0.10533651 | AN34: 0.018341542 | BC34: Alt_6 | BD34: lo | BE34: -hi | BF34: -hi | BI34: -med | BJ34: -3 | BL34: Mauka road | BM34: 9 | BN34: 0 | BO34: -4 | BP34: 2 | BX34: Mauka road | BY34: 2 | BZ34: -4 | CJ34: Mauka road | CK34: 4 | CL34: -4
G35: Alt_5 | H35: HI | I35: HI | K35: V Hi | L35: 115 | N35: Alt_5 | O35: high | P35: 3 | AD35: Alt_6 | AE35: med-hi | AF35: 4 | AH35: none | AI35: 0 | AL35: Mauka road | AM35: 0.012269509 | AN35: 0.0023559799 | BC35: Alt_7 | BD35: med | BE35: -hi | BF35: -hi | BI35: -lo-med | BJ35: -2 | BL35: Mauka road | BM35: 9 | BN35: 0 | BO35: -4 | BP35: 2 | BX35: Mauka road | BY35: 2 | BZ35: -4 | CJ35: Mauka road | CK35: 4 | CL35: -4
G36: Alt_6 | H36: V Hi | I36: HI | K36: VV Hi | L36: 145 | N36: Alt_6 | O36: high | P36: 3 | AD36: Alt_7 | AE36: hi | AF36: 5 | AH36: lo | AI36: 1 | AL36: Mauka road | AM36: 0.058799051 | AN36: 0.010994573 | BC36: Alt_8 | BD36: lo | BE36: lo | BF36: lo | BI36: none | BJ36: 0 | BL36: Mauka road | BM36: 9 | BN36: 0 | BO36: -8 | BP36: 4 | BX36: Mauka road | BY36: 2 | BZ36: -4 | CJ36: Mauka road | CK36: 4 | CL36: -4
G37: Alt_7 | H37: VV Hi | I37: V Hi | N37: Alt_7 | O37: high | P37: 3 | AD37: Alt_8 | AE37: low-med | AF37: 2 | AH37: low-med | AI37: 2 | AL37: Mauka road | AM37: 0.42201394 | AN37: 0.084815277 | BC37: Alt_9 | BD37: lo | BE37: -med | BF37: -hi | BI37: lo | BJ37: 1 | BL37: Mauka road | BM37: 9 | BN37: 0 | BO37: -8 | BP37: 4 | BX37: Mauka road | BY37: 2 | BZ37: -4 | CJ37: Mauka road | CK37: 4 | CL37: -4
G38: Alt_8 | H38: Lo | I38: Lo | N38: Alt_8 | O38: med | P38: 2 | AD38: Alt_9 | AE38: med | AF38: 3 | AH38: med | AI38: 3 | AL38: Mauka road | AM38: 1 | AN38: 0.150892 | BC38: Alt_10 | BD38: lo-med | BE38: lo-med | BF38: lo-med | BI38: lo-med | BJ38: 2 | BL38: Mauka road | BM38: 9 | BN38: 0 | BO38: -56 | BP38: 28 | BX38: Mauka road | BY38: 2 | BZ38: -4 | CJ38: Mauka road | CK38: 4 | CL38: -4
G39: Alt_9 | H39: HI | I39: Med-Hi | N39: Alt_9 | O39: high | P39: 3 | AD39: Alt_10 | AE39: hi | AF39: 5 | AH39: med-hi | AI39: 4 | AL39: Mauka road | AM39: 0.0032888576 | AN39: 0.00041436873 | BC39: Alt_11 | BD39: none | BE39: none | BF39: none | BI39: med | BJ39: 3 | BL39: Mauka road | BM39: 9 | BN39: 0 | BX39: Mauka road | BY39: 2 | BZ39: -4 | CJ39: Mauka road | CK39: 4 | CL39: -4
G40: Alt_10 | H40: NA | I40: Med-Hi | N40: Alt_10 | O40: Low | P40: 1 | AD40: Alt_11 | AE40: none | AF40: 0 | AH40: hi | AI40: 5 | AL40: Mauka road | AM40: 0.0059852793 | AN40: 0.00047743579 | BI40: hi | BJ40: 4 | BL40: Mauka road | BM40: 3 | BN40: 0 | BX40: Mauka road | BY40: 4 | BZ40: -8 | CJ40: Mauka road | CK40: 8 | CL40: -8
N41: Alt_11 | O41: None | P41: 0 | AL41: Mauka road | AM41: 0.0081080348 | AN41: 0.0010621466 | BL41: Mauka road | BM41: 3 | BN41: 0 | BX41: Mauka road | BY41: 4 | BZ41: -8 | CJ41: Mauka road | CK41: 8 | CL41: -8
AD42: note: add 1 to each score | AN42: 0.27609915 | BN42: 0 | BZ42: -56 | CL42: -56
B43: *Shared borders between paddocks | AN43: 1.652321 | BN43: 96 | BZ43: 28 | CL43: 56
B44: paddock_a | C44: paddock_b | D44: length_meters | E44: fence | F44: firebreak | G44: fence+firebreak (all alternatives except 3, 10, 11)
A45: 2 | B45: 1 | C45: 2 | D45: 1090.92 | E45: 80728.08 | F45: 63142.45 | G45: 143870.53
A46: 3 | B46: 1 | C46: 3 | D46: 1295.38 | E46: 95858.12 | F46: 74976.594 | G46: 170834.71
A47: 4 | B47: 1 | C47: 4 | D47: 667.706 | E47: 49410.244 | F47: 38646.823 | G47: 88057.067
A48: 25 | B48: 2 | C48: 3 | D48: 539.1 | E48: 39893.4 | F48: 31203.108 | G48: 71096.508
A49: 28 | B49: 2 | C49: 6 | D49: 62.1377 | E49: 4598.1898 | F49: 3596.5301 | G49: 8194.7199
...

Sheet cleaned
A1: Area | B1: Elevation | C1: Paddock size (m2) | D1: Management Unit | E1: COST_Alt_1 | F1: COST_Alt_2 | G1: COST_Alt_3 | H1: COST_Alt_4 | I1: COST_Alt_5 | J1: COST_Alt_6 | K1: COST_Alt_7 | L1: COST_Alt_8 | M1: COST_Alt_9 | N1: COST_Alt_10 | O1: COST_Alt_11 | P1: FIRE_Alt_1 | Q1: FIRE_Alt_2 | R1: FIRE_Alt_3 | S1: FIRE_Alt_4 | T1: FIRE_Alt_5 | U1: FIRE_Alt_6 | V1: FIRE_Alt_7 | W1: FIRE_Alt_8 | X1: FIRE_Alt_9 | Y1: FIRE_Alt_10 | Z1: FIRE_Alt_11 | AA1: R&E_Alt_1 | AB1: R&E_Alt_2 | AC1: R&E_Alt_3 | AD1: R&E_Alt_4 | AE1: R&E_Alt_5 | AF1: R&E_Alt_6 | AG1: R&E_Alt_7 | AH1: R&E_Alt_8 | AI1: R&E_Alt_9 | AJ1: R&E_Alt_10 | AK1: R&E_Alt_11 | AL1: FOREST_Alt_1 | AM1: FOREST_Alt_2 | AN1: FOREST_Alt_3 | AO1: FOREST_Alt_4 | AP1: FOREST_Alt_5 | AQ1: FOREST_Alt_6 | AR1: FOREST_Alt_7 | AS1: FOREST_Alt_8 | AT1: FOREST_Alt_9 | AU1: FOREST_Alt_10 | AV1: FOREST_Alt_11 | AW1: COMMUNITY_Alt_1 | AX1: COMMUNITY_Alt_2 | AY1: COMMUNITY_Alt_3 | AZ1: COMMUNITY_Alt_4 | BA1: COMMUNITY_Alt_5 | BB1: COMMUNITY_Alt_6 | BC1: COMMUNITY_Alt_7 | BD1: COMMUNITY_Alt_8 | BE1: COMMUNITY_Alt_9 | BF1: COMMUNITY_Alt_10 | BG1: COMMUNITY_Alt_11 | BH1: HUNTERS_Alt_1 | BI1: HUNTERS_Alt_2 | BJ1: HUNTERS_Alt_3 | BK1: HUNTERS_Alt_4 | BL1: HUNTERS_Alt_5 | BM1: HUNTERS_Alt_6 | BN1: HUNTERS_Alt_7 | BO1: HUNTERS_Alt_8 | BP1: HUNTERS_Alt_9 | BQ1: HUNTERS_Alt_10 | BR1: HUNTERS_Alt_11 | BS1: RANCHERS_Alt_1 | BT1: RANCHERS_Alt_2 | BU1: RANCHERS_Alt_3 | BV1: RANCHERS_Alt_4 | BW1: RANCHERS_Alt_5 | BX1: RANCHERS_Alt_6 | BY1: RANCHERS_Alt_7 | BZ1: RANCHERS_Alt_8 | CA1: RANCHERS_Alt_9 | CB1: RANCHERS_Alt_10 | CC1: RANCHERS_Alt_11
A2: Puu Waawaa | B2: Makai | C2: 488554 | D2: 1 | E2: 802403.5 | F2: =paddock_data!G3 -> 1686.8636 | G2: 945878.42 | H2: 802403.5 | I2: 1291900.1 | J2: 1291900.1 | K2: 1994685 | L2: 802403.5 | M2: 802403.5 | N2: 578767.95 | O2: 0 | P2: 0.52966491 | Q2: 0.21186596 | R2: 0.52966491 | S2: 0.52966491 | T2: 0.52966491 | U2: 0.52966491 | V2: 0.60123687 | W2: 0.52966491 | X2: 0.52966491 | Y2: 0 | Z2: 0 | AA2: 0 | AB2: 0 | AC2: 0 | AD2: 0 | AE2: 0 | AF2: 0 | AG2: 0 | AH2: 0 | AI2: 0 | AJ2: 0 | AK2: 0 | AL2: 0.0036574588 | AM2: 0.0025286094 | AN2: 0.0018814155 | AO2: 0.0045454804 | AP2: 0.0045454804 | AQ2: 0.005433502 | AR2: 0.0083517966 | AS2: 0.004440108 | AT2: 0.0072095452 | AU2: 0.004440108 | AV2: 0.0017760432 | AW2: 3 | AX2: 9 | AY2: 9 | AZ2: 3 | BA2: 3 | BB2: 3 | BC2: 9 | BD2: 3 | BE2: 3 | BF2: 6 | BG2: 0 | BH2: 1 | BI2: 1 | BJ2: 1 | BK2: -2 | BL2: -4 | BM2: -4 | BN2: -4 | BO2: 1 | BP2: -3 | BQ2: 2 | BR2: 0 | BS2: 3 | BT2: 1 | BU2: 4 | BV2: -4 | BW2: -4 | BX2: -4 | BY2: -4 | BZ2: 1 | CA2: -4 | CB2: 2 | CC2: 0
A3: Puu Waawaa | B3: Makai | C3: 564453 | D3: 2 | E3: 585346.4 | F3: =paddock_data!G4 -> 1948.9253 | G3: 702251.94 | H3: 585346.4 | I3: 953029.72 | J3: 953937.33 | K3: 1765903 | L3: 586254.01 | M3: 586254.01 | N3: 478274.74 | O3: 0 | P3: 0.79747096 | Q3: 0.31898838 | R3: 0.79747096 | S3: 0.79747096 | T3: 0.79747096 | U3: 0.79747095 | V3: 1 | W3: 0.79747095 | X3: 0.79747095 | Y3: 0 | Z3: 0 | AA3: 0.0030568155 | AB3: 0.0019295202 | AC3: 0.0018788255 | AD3: 0.0036458105 | AE3: 0.0036458105 | AF3: 0.0042348055 | AG3: 0.0064789447 | AH3: 0.0029449749 | AI3: 0.0054127954 | AJ3: 0.0029449749 | AK3: 0.00117799 | AL3: 0.0013281637 | AM3: 0.0008383622 | AN3: 0.00081633576 | AO3: 0.0015840776 | AP3: 0.0015840776 | AQ3: 0.0018399915 | AR3: 0.0028150534 | AS3: 0.0012795697 | AT3: 0.0023518194 | AU3: 0.0012795697 | AV3: 0.00051182789 | AW3: 3 | AX3: 9 | AY3: 9 | AZ3: 3 | BA3: 3 | BB3: 3 | BC3: 9 | BD3: 3 | BE3: 3 | BF3: 6 | BG3: 0 | BH3: 1 | BI3: 1 | BJ3: 1 | BK3: -2 | BL3: -4 | BM3: -4 | BN3: -4 | BO3: 1 | BP3: -3 | BQ3: 2 | BR3: 0 | BS3: 3 | BT3: 1 | BU3: 4 | BV3: -4 | BW3: -4 | BX3: -4 | BY3: -4 | BZ3: 1 | CA3: -4 | CB3: 2 | CC3: 0
A4: Puu Waawaa | B4: Makai | C4: 804948 | D4: 3 | E4: 543880.34 | F4: =paddock_data!G5 -> 2779.2987 | G4: 655710.13 | H4: 543880.34 | I4: 888292.75 | J4: 890642.26 | K4: 2048560 | L4: 546229.85 | M4: 546229.85 | N4: 522558.88 | O4: 0 | P4: 0.49385319 | Q4: 0.19754128 | R4: 0.49385319 | S4: 0.49385319 | T4: 0.49385319 | U4: 0.49412888 | V4: 0.58139776 | W4: 0.49412888 | X4: 0.49412888 | Y4: 0 | Z4: 0 | AA4: 0.0070244945 | AB4: 0.0049301797 | AC4: 0.0034905246 | AD4: 0.0087914794 | AE4: 0.0087914794 | AF4: 0.010560413 | AG4: 0.016478179 | AH4: 0.0088349247 | AI4: 0.014094383 | AJ4: 0.0088349247 | AK4: 0.0035339699 | AL4: 0.015794586 | AM4: 0.011085517 | AN4: 0.0078484498 | AO4: 0.019767655 | AP4: 0.019767655 | AQ4: 0.023745104 | AR4: 0.03705121 | AS4: 0.019865341 | AT4: 0.031691241 | AU4: 0.019865341 | AV4: 0.0079461366 | AW4: 3 | AX4: 9 | AY4: 9 | AZ4: 3 | BA4: 3 | BB4: 3 | BC4: 9 | BD4: 3 | BE4: 3 | BF4: 6 | BG4: 0 | BH4: 1 | BI4: 1 | BJ4: 1 | BK4: -2 | BL4: -4 | BM4: -4 | BN4: -4 | BO4: 1 | BP4: -3 | BQ4: 2 | BR4: 0 | BS4: 3 | BT4: 1 | BU4: 4 | BV4: -4 | BW4: -4 | BX4: -4 | BY4: -4 | BZ4: 1 | CA4: -4 | CB4: 2 | CC4: 0
A5: Puu Waawaa | B5: Makai | C5: 704315 | D5: 4 | E5: 460198.98 | F5: =paddock_data!G6 -> 2431.8363 | G5: 561785.56 | H5: 460198.98 | I5: 757649.11 | J5: 759681.45 | K5: 1772838.6 | L5: 462231.32 | M5: 462231.32 | N5: 447328.78 | O5: 0 | P5: 0.33064545 | Q5: 0.13225818 | R5: 0.33064545 | S5: 0.33064545 | T5: 0.33064545 | U5: 0.33064544 | V5: 0.40876937 | W5: 0.33064544 | X5: 0.33064544 | Y5: 0 | Z5: 0 | AA5: 0.005218624 | AB5: 0.0039722335 | AC5: 0.0020773175 | AD5: 0.0067892773 | AE5: 0.0067892773 | AF5: 0.0083599304 | AG5: 0.013562713 | AH5: 0.0078532664 | AI5: 0.011501237 | AJ5: 0.0078532664 | AK5: 0.0031413065 | AL5: 0.0067555995 | AM5: 0.0051421254 | AN5: 0.0026891236 | AO5: 0.0087888375 | AP5: 0.0087888375 | AQ5: 0.010822075 | AR5: 0.017557167 | AS5: 0.01016619 | AT5: 0.014888551 | AU5: 0.01016619 | AV5: 0.0040664759 | AW5: 3 | AX5: 9 | AY5: 9 | AZ5: 3 | BA5: 3 | BB5: 3 | BC5: 9 | BD5: 3 | BE5: 3 | BF5: 6 | BG5: 0 | BH5: 1 | BI5: 1 | BJ5: 1 | BK5: -2 | BL5: -4 | BM5: -4 | BN5: -4 | BO5: 1 | BP5: -3 | BQ5: 2 | BR5: 0 | BS5: 3 | BT5: 1 | BU5: 4 | BV5: -4 | BW5: -4 | BX5: -4 | BY5: -4 | BZ5: 1 | CA5: -4 | CB5: 2 | CC5: 0
A6: Puu Waawaa | B6: Makai | C6: 2172640 | D6: 5 | E6: 906962.98 | F6: =paddock_data!G7 -> 7501.622 | G6: 1063236.8 | H6: 906962.98 | I6: 1455138.7 | J6: 1467222.2 | K6: 4592564.8 | L6: 919046.47 | M6: 919046.47 | N6: 1110506.9 | O6: 0 | P6: 0.40267765 | Q6: 0.16107106 | R6: 0.40267765 | S6: 0.40267765 | T6: 0.40267765 | U6: 0.40383331 | V6: 0.56260033 | W6: 0.40383331 | X6: 0.40383331 | Y6: 0 | Z6: 0 | AA6: 0.041116015 | AB6: 0.030111089 | AC6: 0.018341542 | AD6: 0.052503251 | AE6: 0.052503251 | AF6: 0.063943126 | AG6: 0.10533651 | AH6: 0.056936181 | AI6: 0.086717598 | AJ6: 0.056936181 | AK6: 0.022774472 | AL6: 0.041341203 | AM6: 0.030276004 | AN6: 0.018441997 | AO6: 0.052790805 | AP6: 0.052790805 | AQ6: 0.064293335 | AR6: 0.10591342 | AS6: 0.057248014 | AT6: 0.087192541 | AU6: 0.057248014 | AV6: 0.022899206 | AW6: 3 | AX6: 9 | AY6: 9 | AZ6: 3 | BA6: 3 | BB6: 3 | BC6: 9 | BD6: 3 | BE6: 3 | BF6: 6 | BG6: 0 | BH6: 1 | BI6: 1 | BJ6: 1 | BK6: -2 | BL6: -4 | BM6: -4 | BN6: -4 | BO6: 1 | BP6: -3 | BQ6: 2 | BR6: 0 | BS6: 3 | BT6: 1 | BU6: 4 | BV6: -4 | BW6: -4 | BX6: -4 | BY6: -4 | BZ6: 1 | CA6: -4 | CB6: 2 | CC6: 0
A7: Puu Waawaa | B7: Makai | C7: 3072920 | D7: 6 | E7: 958827.22 | F7: =paddock_data!G8 -> 10610.08 | G7: 1121449.6 | H7: 958827.22 | I7: 1536109.3 | J7: 1537234.3 | K7: 5957629.7 | L7: 959952.18 | M7: 959952.18 | N7: 1392501.9 | O7: 0 | P7: 0.6216904 | Q7: 0.24867616 | R7: 0.6216904 | S7: 0.6216904 | T7: 0.6216904 | U7: 0.62174413 | V7: 0.85390778 | W7: 0.62174413 | X7: 0.62174413 | Y7: 0 | Z7: 0 | AA7: 0.0052853601 | AB7: 0.003527732 | AC7: 0.0029293802 | AD7: 0.00646335 | AE7: 0.00646335 | AF7: 0.0076415932 | AG7: 0.012269509 | AH7: 0.0058899498 | AI7: 0.0099975731 | AJ7: 0.0058899498 | AK7: 0.0023559799 | AL7: 0.017521934 | AM7: 0.011695076 | AN7: 0.0097114305 | AO7: 0.021427186 | AP7: 0.021427186 | AQ7: 0.025333278 | AR7: 0.040675664 | AS7: 0.01952626 | AT7: 0.033143782 | AU7: 0.01952626 | AV7: 0.0078105039 | AW7: 3 | AX7: 9 | AY7: 9 | AZ7: 3 | BA7: 3 | BB7: 3 | BC7: 9 | BD7: 3 | BE7: 3 | BF7: 6 | BG7: 0 | BH7: 1 | BI7: 1 | BJ7: 1 | BK7: -2 | BL7: -4 | BM7: -4 | BN7: -4 | BO7: 1 | BP7: -3 | BQ7: 2 | BR7: 0 | BS7: 3 | BT7: 1 | BU7: 4 | BV7: -4 | BW7: -4 | BX7: -4 | BY7: -4 | BZ7: 1 | CA7: -4 | CB7: 2 | CC7: 0
A8: Puu Waawaa | B8: Makai | C8: 2220560 | D8: 7 | E8: 915650.33 | F8: =paddock_data!G9 -> 7667.0786 | G8: 1072987.5 | H8: 915650.33 | I8: 1468701.4 | J8: 1475524.1 | K8: 4669799.7 | L8: 922472.99 | M8: 922472.99 | N8: 1128843 | O8: 0 | P8: 0.66739253 | Q8: 0.26695701 | R8: 0.66739253 | S8: 0.66739253 | T8: 0.66739253 | U8: 0.6673925 | V8: 0.92400342 | W8: 0.6673925 | X8: 0.6673925 | Y8: 0 | Z8: 0 | AA8: 0.025669964 | AB8: 0.01686473 | AC8: 0.014675392 | AD8: 0.031167251 | AE8: 0.031167251 | AF8: 0.036664537 | AG8: 0.058799051 | AH8: 0.027486432 | AI8: 0.04765911 | AJ8: 0.027486432 | AK8: 0.010994573 | AL8: 0.012499801 | AM8: 0.0082121563 | AN8: 0.0071460743 | AO8: 0.015176664 | AP8: 0.015176664 | AQ8: 0.017853527 | AR8: 0.028631767 | AS8: 0.013384317 | AT8: 0.023207254 | AU8: 0.013384317 | AV8: 0.0053537266 | AW8: 3 | AX8: 9 | AY8: 9 | AZ8: 3 | BA8: 3 | BB8: 3 | BC8: 9 | BD8: 3 | BE8: 3 | BF8: 6 | BG8: 0 | BH8: 1 | BI8: 1 | BJ8: 1 | BK8: -2 | BL8: -4 | BM8: -4 | BN8: -4 | BO8: 1 | BP8: -3 | BQ8: 2 | BR8: 0 | BS8: 3 | BT8: 1 | BU8: 4 | BV8: -4 | BW8: -4 | BX8: -4 | BY8: -4 | BZ8: 1 | CA8: -4 | CB8: 2 | CC8: 0
A9: Puu Waawaa | B9: Makai | C9: 1492830 | D9: 8 | E9: 703316.8 | F9: =paddock_data!G10 -> 5154.3957 | G9: 834662.79 | H9: 703316.8 | I9: 1137205.5 | J9: 1177552.8 | K9: 3324988.7 | L9: 743664.02 | M9: 743664.02 | N9: 805261.26 | O9: 0 | P9: 0.52369912 | Q9: 0.20947965 | R9: 0.52369912 | S9: 0.52369912 | T9: 0.52369912 | U9: 0.52537476 | V9: 0.73784156 | W9: 0.52537476 | X9: 0.52537476 | Y9: 0 | Z9: 0 | AA9: 0.17365065 | AB9: 0.12034943 | AC9: 0.088835371 | AD9: 0.21605829 | AE9: 0.21605829 | AF9: 0.25875016 | AG9: 0.42201394 | AH9: 0.21203819 | AI9: 0.34356544 | AJ9: 0.21203819 | AK9: 0.084815277 | AL9: 0.0029655987 | AM9: 0.0020553226 | AN9: 0.0015171268 | AO9: 0.0036898346 | AP9: 0.0036898346 | AQ9: 0.0044189248 | AR9: 0.0072071369 | AS9: 0.0036211796 | AT9: 0.0058673966 | AU9: 0.0036211796 | AV9: 0.0014484718 | AW9: 3 | AX9: 9 | AY9: 9 | AZ9: 3 | BA9: 3 | BB9: 3 | BC9: 9 | BD9: 3 | BE9: 3 | BF9: 6 | BG9: 0 | BH9: 1 | BI9: 1 | BJ9: 1 | BK9: -2 | BL9: -4 | BM9: -4 | BN9: -4 | BO9: 1 | BP9: -3 | BQ9: 2 | BR9: 0 | BS9: 3 | BT9: 1 | BU9: 4 | BV9: -4 | BW9: -4 | BX9: -4 | BY9: -4 | BZ9: 1 | CA9: -4 | CB9: 2 | CC9: 0
A10: Puu Waawaa | B10: Makai | C10: 1715970 | D10: 9 | E10: 827824.48 | F10: =paddock_data!G11 -> 5924.8464 | G10: 974411.12 | H10: 827824.48 | I10: 1331587.4 | J10: 1427781.4 | K10: 3896204.2 | L10: 924018.49 | M10: 924018.49 | N10: 937815.45 | O10: 0 | P10: 0.33127441 | Q10: 0.13250977 | R10: 0.33127441 | S10: 0.33127441 | T10: 0.33127441 | U10: 0.33501021 | V10: 0.44544054 | W10: 0.33501021 | X10: 0.33501021 | Y10: 0 | Z10: 0 | AA10: 0.37863672 | AB10: 0.28810152 | AC10: 0.150892 | AD10: 0.49250909 | AE10: 0.49250909 | AF10: 0.60808307 | AG10: 1 | AH10: 0.56936181 | AI10: 0.83582779 | AJ10: 0.56936181 | AK10: 0.22774472 | AL10: 0.033761037 | AM10: 0.025688492 | AN10: 0.013454243 | AO10: 0.043914434 | AP10: 0.043914434 | AQ10: 0.054219556 | AR10: 0.089164719 | AS10: 0.050766986 | AT10: 0.07452635 | AU10: 0.050766986 | AV10: 0.020306794 | AW10: 3 | AX10: 9 | AY10: 9 | AZ10: 3 | BA10: 3 | BB10: 3 | BC10: 9 | BD10: 3 | BE10: 3 | BF10: 6 | BG10: 0 | BH10: 1 | BI10: 1 | BJ10: 1 | BK10: -2 | BL10: -4 | BM10: -4 | BN10: -4 | BO10: 1 | BP10: -3 | BQ10: 2 | BR10: 0 | BS10: 3 | BT10: 1 | BU10: 4 | BV10: -4 | BW10: -4 | BX10: -4 | BY10: -4 | BZ10: 1 | CA10: -4 | CB10: 2 | CC10: 0
A11: Puu Waawaa | B11: Makai | C11: 1513710 | D11: 10 | E11: 847549.75 | F11: =paddock_data!G12 -> 5226.4895 | G11: 996550.9 | H11: 847549.75 | I11: 1362382.5 | J11: 1362987.6 | K11: 3540459.5 | L11: 848154.82 | M11: 848154.82 | N11: 892070.51 | O11: 0 | P11: 0.26381935 | Q11: 0.10552774 | R11: 0.26381935 | S11: 0.26381935 | T11: 0.26381935 | U11: 0.26605521 | V11: 0.34394247 | W11: 0.26605521 | X11: 0.26605521 | Y11: 0 | Z11: 0 | AA11: 0.0011996954 | AB11: 0.00095107413 | AC11: 0.00041436873 | AD11: 0.0015923587 | AE11: 0.0015923587 | AF11: 0.0019885338 | AG11: 0.0032888576 | AH11: 0.0019633166 | AI11: 0.0027738604 | AJ11: 0.0019633166 | AK11: 0.00078532664 | AL11: 0.0053168454 | AM11: 0.0042149984 | AN11: 0.0018364116 | AO11: 0.0070570623 | AP11: 0.0070570623 | AQ11: 0.0088128427 | AR11: 0.014575656 | AS11: 0.0087010845 | AT11: 0.012293277 | AU11: 0.0087010845 | AV11: 0.0034804338 | AW11: 3 | AX11: 9 | AY11: 9 | AZ11: 3 | BA11: 3 | BB11: 3 | BC11: 9 | BD11: 3 | BE11: 3 | BF11: 6 | BG11: 0 | BH11: 1 | BI11: 1 | BJ11: 1 | BK11: -2 | BL11: -4 | BM11: -4 | BN11: -4 | BO11: 1 | BP11: -3 | BQ11: 2 | BR11: 0 | BS11: 3 | BT11: 1 | BU11: 4 | BV11: -4 | BW11: -4 | BX11: -4 | BY11: -4 | BZ11: 1 | CA11: -4 | CB11: 2 | CC11: 0
A12: Puu Waawaa | B12: Middle | C12: 1680430 | D12: 11 | E12: 729595.18 | F12: =paddock_data!G13 -> 5802.135 | G12: 864157.83 | H12: 729595.18 | I12: 1178231.4 | J12: 1179441.6 | K12: 3596740.1 | L12: 730805.32 | M12: 730805.32 | N12: 872705.62 | O12: 0 | P12: 0.15198637 | Q12: 0.06079455 | R12: 0.15198637 | S12: 0.15198637 | T12: 0.15198637 | U12: 0.15208305 | V12: 0.15534709 | W12: 0.15208305 | X12: 0.15208305 | Y12: 0 | Z12: 0 | AA12: 0.0020480891 | AB12: 0.0017616276 | AC12: 0.00047743579 | AD12: 0.0028334157 | AE12: 0.0028334157 | AF12: 0.003619046 | AG12: 0.0059852793 | AH12: 0.0039266332 | AI12: 0.0051896993 | AJ12: 0.0039266332 | AK12: 0.0015706533 | AL12: 0.00032702594 | AM12: 0.00028128558 | AN12: 7.6233936e-05 | AO12: 0.00045242195 | AP12: 0.00045242195 | AQ12: 0.00057786644 | AR12: 0.00095569165 | AS12: 0.00062698002 | AT12: 0.00082865845 | AU12: 0.00062698002 | AV12: 0.00025079201 | AW12: 1 | AX12: 3 | AY12: 3 | AZ12: 1 | BA12: 1 | BB12: 1 | BC12: 3 | BD12: 1 | BE12: 1 | BF12: 2 | BG12: 0 | BH12: 2 | BI12: 2 | BJ12: 2 | BK12: -4 | BL12: -8 | BM12: -8 | BN12: -8 | BO12: 2 | BP12: -6 | BQ12: 4 | BR12: 0 | BS12: 6 | BT12: 2 | BU12: 8 | BV12: -8 | BW12: -8 | BX12: -8 | BY12: -8 | BZ12: 2 | CA12: -8 | CB12: 4 | CC12: 0
A13: Puu Waawaa | B13: Middle | C13: 2169210 | D13: 12 | E13: 823798.7 | F13: =paddock_data!G14 -> 7489.779 | G13: 969892.55 | H13: 823798.7 | I13: 1325302.3 | J13: 1326785.9 | K13: 4447194.5 | L13: 825282.27 | M13: 825282.27 | N13: 1062871.3 | O13: 0 | P13: 0.27049805 | Q13: 0.10819922 | R13: 0.27049805 | S13: 0.27049805 | T13: 0.27049805 | U13: 0.27052038 | V13: 0.31488215 | W13: 0.27052038 | X13: 0.27052038 | Y13: 0 | Z13: 0 | AA13: 0.0030254632 | AB13: 0.0023881752 | AC13: 0.0010621466 | AD13: 0.0040071215 | AE13: 0.0040071215 | AF13: 0.0049888675 | AG13: 0.0081080348 | AH13: 0.0049082915 | AI13: 0.0069521841 | AJ13: 0.0049082915 | AK13: 0.0019633166 | AL13: 0.029447072 | AM13: 0.023244298 | AN13: 0.010337957 | AO13: 0.03900163 | AP13: 0.03900163 | AQ13: 0.048557041 | AR13: 0.078916143 | AS13: 0.047772788 | AT13: 0.067666156 | AU13: 0.047772788 | AV13: 0.019109115 | AW13: 1 | AX13: 3 | AY13: 3 | AZ13: 1 | BA13: 1 | BB13: 1 | BC13: 3 | BD13: 1 | BE13: 1 | BF13: 2 | BG13: 0 | BH13: 2 | BI13: 2 | BJ13: 2 | BK13: -4 | BL13: -8 | BM13: -8 | BN13: -8 | BO13: 2 | BP13: -6 | BQ13: 4 | BR13: 0 | BS13: 6 | BT13: 2 | BU13: 8 | BV13: -8 | BW13: -8 | BX13: -8 | BY13: -8 | BZ13: 2 | CA13: -8 | CB13: 4 | CC13: 0
... A23: Puu Waawaa | B23: Mauka | C23: 3550930 | D23: 22 | E23: 652397.95 | F23: =paddock_data!G24 -> 12260.538 | G23: 1195902.2 | H23: 652397.95 | I23: 1266906.4 | J23: 1267917.2 | K23: 2315086.5 | L23: 653408.73 | M23: 653408.73 | N23: 965669.57 | O23: 0 | P23: 0.43846768 | Q23: 0.17538707 | R23: 0.43846768 | S23: 0.43846768 | T23: 0.43846768 | U23: 0.43846768 | V23: 0.55906795 | W23: 0.43846768 | X23: 0.43846768 | Y23: 0 | Z23: 0 | AA23: 0.004422022 | AB23: 0.0031823967 | AC23: 0.0020660421 | AD23: 0.0056000119 | AE23: 0.0056000119 | AF23: 0.0067780019 | AG23: 0.010880235 | AH23: 0.0058899498 | AI23: 0.0091339818 | AJ23: 0.0058899498 | AK23: 0.0023559799 | AL23: 0.11197554 | AM23: 0.080585442 | AN23: 0.052316832 | AO23: 0.1418049 | AP23: 0.1418049 | AQ23: 0.17163425 | AR23: 0.27551203 | AS23: 0.14914677 | AT23: 0.23129296 | AU23: 0.14914677 | AV23: 0.05965871 | AW23: 2 | AX23: 6 | AY23: 6 | AZ23: 2 | BA23: 2 | BB23: 2 | BC23: 6 | BD23: 2 | BE23: 2 | BF23: 4 | BG23: 0 | BH23: 3 | BI23: 3 | BJ23: 3 | BK23: -6 | BL23: -12 | BM23: -12 | BN23: -12 | BO23: 3 | BP23: -9 | BQ23: 6 | BR23: 0 | BS23: 9 | BT23: 3 | BU23: 12 | BV23: -12 | BW23: -12 | BX23: -12 | BY23: -12 | BZ23: 3 | CA23: -12 | CB23: 6 | CC23: 0

Sheet pivot
A3: Sum of COST_Alt_11 | B3: Sum of RANCHERS_Alt_11 | C3: Sum of HUNTERS_Alt_11 | D3: Sum of COMMUNITY_Alt_11 | E3: Sum of FOREST_Alt_11 | F3: Sum of R&E_Alt_11 | G3: Sum of FIRE_Alt_11
A4: 0 | B4: 0 | C4: 0 | D4: 0 | E4: 0.64097803 | F4: 0.39776794 | G4: 0

Sheet People
C1: Community | P1: Hunters | AC1: Grazing
C2: Alt_1 | D2: Alt_2 | E2: Alt_3 | F2: Alt_4 | G2: Alt_5 | H2: Alt_6 | I2: Alt_7 | J2: Alt_8 | K2: Alt_9 | L2: Alt_10 | M2: Alt_11 | P2: Alt_1 | Q2: Alt_2 | R2: Alt_3 | S2: Alt_4 | T2: Alt_5 | U2: Alt_6 | V2: Alt_7 | W2: Alt_8 | X2: Alt_9 | Y2: Alt_10 | AC2: Alt_1 | AD2: Alt_2 | AE2: Alt_3 | AF2: Alt_4 | AG2: Alt_5 | AH2: Alt_6 | AI2: Alt_7 | AJ2: Alt_8 | AK2: Alt_9 | AL2: Alt_10 | AP2: Alt_1 | AQ2: Alt_2 | AR2: Alt_3 | AS2: Alt_4 | AT2: Alt_5 | AU2: Alt_6 | AV2: Alt_7 | AW2: Alt_8 | AX2: Alt_9 | AY2: Alt_10 | AZ2: Alt_11 | BB2: Alt_1 | BC2: Alt_2 | BD2: Alt_3 | BE2: Alt_4 | BF2: Alt_5 | BG2: Alt_6 | BH2: Alt_7 | BI2: Alt_8 | BJ2: Alt_9 | BK2: Alt_10 | BN2: Alt_1 | BO2: Alt_2 | BP2: Alt_3 | BQ2: Alt_4 | BR2: Alt_5 | BS2: Alt_6 | BT2: Alt_7 | BU2: Alt_8 | BV2: Alt_9 | BW2: Alt_10
B3: Makai | C3: 3 | D3: 9 | E3: 9 | F3: 3 | G3: 3 | H3: 3 | I3: 9 | J3: 3 | K3: 3 | L3: 6 | M3: 0 | N3: 18 | P3: 1 | Q3: 1 | R3: 1 | S3: -2 | T3: -4 | U3: -4 | V3: -4 | W3: 1 | X3: -3 | Y3: 2 | Z3: 0 | AA3: 3 | AC3: 3 | AD3: 1 | AE3: 4 | AF3: -4 | AG3: -4 | AH3: -4 | AI3: -4 | AJ3: 1 | AK3: -4 | AL3: 2 | AM3: 0 | AN3: 5 | AP3: 0.33333333 | AQ3: 1 | AR3: 1 | AS3: 0.33333333 | AT3: 0.33333333 | AU3: 0.33333333 | AV3: 1 | AW3: 0.33333333 | AX3: 0.33333333 | AY3: 0.66666667 | AZ3: 0 | BB3: 0.16666667 | BC3: 0.16666667 | BD3: 0.16666667 | BE3: -0.33333333 | BF3: -0.66666667 | BG3: -0.66666667 | BH3: -0.66666667 | BI3: 0.16666667 | BJ3: -0.5 | BK3: 0.33333333 | BL3: 0 | BN3: 0.25 | BO3: 0.083333333 | BP3: 0.33333333 | BQ3: -0.33333333 | BR3: -0.33333333 | BS3: -0.33333333 | BT3: -0.33333333 | BU3: 0.083333333 | BV3: -0.33333333 | BW3: 0.16666667 | BX3: 0
B4: Makai | C4: 3 | D4: 9 | E4: 9 | F4: 3 | G4: 3 | H4: 3 | I4: 9 | J4: 3 | K4: 3 | L4: 6 | M4: 0 | N4: 18 | P4: 1 | Q4: 1 | R4: 1 | S4: -2 | T4: -4 | U4: -4 | V4: -4 | W4: 1 | X4: -3 | Y4: 2 | Z4: 0 | AA4: 3 | AC4: 3 | AD4: 1 | AE4: 4 | AF4: -4 | AG4: -4 | AH4: -4 | AI4: -4 | AJ4: 1 | AK4: -4 | AL4: 2 | AM4: 0 | AN4: 5 | AP4: 0.33333333 | AQ4: 1 | AR4: 1 | AS4: 0.33333333 | AT4: 0.33333333 | AU4: 0.33333333 | AV4: 1 | AW4: 0.33333333 | AX4: 0.33333333 | AY4: 0.66666667 | AZ4: 0 | BB4: 0.16666667 | BC4: 0.16666667 | BD4: 0.16666667 | BE4: -0.33333333 | BF4: -0.66666667 | BG4: -0.66666667 | BH4: -0.66666667 | BI4: 0.16666667 | BJ4: -0.5 | BK4: 0.33333333 | BL4: 0 | BN4: 0.25 | BO4: 0.083333333 | BP4: 0.33333333 | BQ4: -0.33333333 | BR4: -0.33333333 | BS4: -0.33333333 | BT4: -0.33333333 | BU4: 0.083333333 | BV4: -0.33333333 | BW4: 0.16666667 | BX4: 0
B5: Makai | C5: 3 | D5: 9 | E5: 9 | F5: 3 | G5: 3 | H5: 3 | I5: 9 | J5: 3 | K5: 3 | L5: 6 | M5: 0 | N5: 18 | P5: 1 | Q5: 1 | R5: 1 | S5: -2 | T5: -4 | U5: -4 | V5: -4 | W5: 1 | X5: -3 | Y5: 2 | Z5: 0 | AA5: 3 | AC5: 3 | AD5: 1 | AE5: 4 | AF5: -4 | AG5: -4 | AH5: -4 | AI5: -4 | AJ5: 1 | AK5: -4 | AL5: 2 | AM5: 0 | AN5: 5 | AP5: 0.33333333 | AQ5: 1 | AR5: 1 | AS5: 0.33333333 | AT5: 0.33333333 | AU5: 0.33333333 | AV5: 1 | AW5: 0.33333333 | AX5: 0.33333333 | AY5: 0.66666667 | AZ5: 0 | BB5: 0.16666667 | BC5: 0.16666667 | BD5: 0.16666667 | BE5: -0.33333333 | BF5: -0.66666667 | BG5: -0.66666667 | BH5: -0.66666667 | BI5: 0.16666667 | BJ5: -0.5 | BK5: 0.33333333 | BL5: 0 | BN5: 0.25 | BO5: 0.083333333 | BP5: 0.33333333 | BQ5: -0.33333333 | BR5: -0.33333333 | BS5: -0.33333333 | BT5: -0.33333333 | BU5: 0.083333333 | BV5: -0.33333333 | BW5: 0.16666667 | BX5: 0
B6: Makai | C6: 3 | D6: 9 | E6: 9 | F6: 3 | G6: 3 | H6: 3 | I6: 9 | J6: 3 | K6: 3 | L6: 6 | M6: 0 | N6: 18 | P6: 1 | Q6: 1 | R6: 1 | S6: -2 | T6: -4 | U6: -4 | V6: -4 | W6: 1 | X6: -3 | Y6: 2 | Z6: 0 | AA6: 3 | AC6: 3 | AD6: 1 | AE6: 4 | AF6: -4 | AG6: -4 | AH6: -4 | AI6: -4 | AJ6: 1 | AK6: -4 | AL6: 2 | AM6: 0 | AN6: 5 | AP6: 0.33333333 | AQ6: 1 | AR6: 1 | AS6: 0.33333333 | AT6: 0.33333333 | AU6: 0.33333333 | AV6: 1 | AW6: 0.33333333 | AX6: 0.33333333 | AY6: 0.66666667 | AZ6: 0 | BB6: 0.16666667 | BC6: 0.16666667 | BD6: 0.16666667 | BE6: -0.33333333 | BF6: -0.66666667 | BG6: -0.66666667 | BH6: -0.66666667 | BI6: 0.16666667 | BJ6: -0.5 | BK6: 0.33333333 | BL6: 0 | BN6: 0.25 | BO6: 0.083333333 | BP6: 0.33333333 | BQ6: -0.33333333 | BR6: -0.33333333 | BS6: -0.33333333 | BT6: -0.33333333 | BU6: 0.083333333 | BV6: -0.33333333 | BW6: 0.16666667 | BX6: 0
B7: Makai | C7: 3 | D7: 9 | E7: 9 | F7: 3 | G7: 3 | H7: 3 | I7: 9 | J7: 3 | K7: 3 | L7: 6 | M7: 0 | N7: 18 | P7: 1 | Q7: 1 | R7: 1 | S7: -2 | T7: -4 | U7: -4 | V7: -4 | W7: 1 | X7: -3 | Y7: 2 | Z7: 0 | AA7: 3 | AC7: 3 | AD7: 1 | AE7: 4 | AF7: -4 | AG7: -4 | AH7: -4 | AI7: -4 | AJ7: 1 | AK7: -4 | AL7: 2 | AM7: 0 | AN7: 5 | AP7: 0.33333333 | AQ7: 1 | AR7: 1 | AS7: 0.33333333 | AT7: 0.33333333 | AU7: 0.33333333 | AV7: 1 | AW7: 0.33333333 | AX7: 0.33333333 | AY7: 0.66666667 | AZ7: 0 | BB7: 0.16666667 | BC7: 0.16666667 | BD7: 0.16666667 | BE7: -0.33333333 | BF7: -0.66666667 | BG7: -0.66666667 | BH7: -0.66666667 | BI7: 0.16666667 | BJ7: -0.5 | BK7: 0.33333333 | BL7: 0 | BN7: 0.25 | BO7: 0.083333333 | BP7: 0.33333333 | BQ7: -0.33333333 | BR7: -0.33333333 | BS7: -0.33333333 | BT7: -0.33333333 | BU7: 0.083333333 | BV7: -0.33333333 | BW7: 0.16666667 | BX7: 0
B8: Makai | C8: 3 | D8: 9 | E8: 9 | F8: 3 | G8: 3 | H8: 3 | I8: 9 | J8: 3 | K8: 3 | L8: 6 | M8: 0 | N8: 18 | P8: 1 | Q8: 1 | R8: 1 | S8: -2 | T8: -4 | U8: -4 | V8: -4 | W8: 1 | X8: -3 | Y8: 2 | Z8: 0 | AA8: 3 | AC8: 3 | AD8: 1 | AE8: 4 | AF8: -4 | AG8: -4 | AH8: -4 | AI8: -4 | AJ8: 1 | AK8: -4 | AL8: 2 | AM8: 0 | AN8: 5 | AP8: 0.33333333 | AQ8: 1 | AR8: 1 | AS8: 0.33333333 | AT8: 0.33333333 | AU8: 0.33333333 | AV8: 1 | AW8: 0.33333333 | AX8: 0.33333333 | AY8: 0.66666667 | AZ8: 0 | BB8: 0.16666667 | BC8: 0.16666667 | BD8: 0.16666667 | BE8: -0.33333333 | BF8: -0.66666667 | BG8: -0.66666667 | BH8: -0.66666667 | BI8: 0.16666667 | BJ8: -0.5 | BK8: 0.33333333 | BL8: 0 | BN8: 0.25 | BO8: 0.083333333 | BP8: 0.33333333 | BQ8: -0.33333333 | BR8: -0.33333333 | BS8: -0.33333333 | BT8: -0.33333333 | BU8: 0.083333333 | BV8: -0.33333333 | BW8: 0.16666667 | BX8: 0
B9: Makai | C9: 3 | D9: 9 | E9: 9 | F9: 3 | G9: 3 | H9: 3 | I9: 9 | J9: 3 | K9: 3 | L9: 6 | M9: 0 | N9: 18 | P9: 1 | Q9: 1 | R9: 1 | S9: -2 | T9: -4 | U9: -4 | V9: -4 | W9: 1 | X9: -3 | Y9: 2 | Z9: 0 | AA9: 3 | AC9: 3 | AD9: 1 | AE9: 4 | AF9: -4 | AG9: -4 | AH9: -4 | AI9: -4 | AJ9: 1 | AK9: -4 | AL9: 2 | AM9: 0 | AN9: 5 | AP9: 0.33333333 | AQ9: 1 | AR9: 1 | AS9: 0.33333333 | AT9: 0.33333333 | AU9: 0.33333333 | AV9: 1 | AW9: 0.33333333 | AX9: 0.33333333 | AY9: 0.66666667 | AZ9: 0 | BB9: 0.16666667 | BC9: 0.16666667 | BD9: 0.16666667 | BE9: -0.33333333 | BF9: -0.66666667 | BG9: -0.66666667 | BH9: -0.66666667 | BI9: 0.16666667 | BJ9: -0.5 | BK9: 0.33333333 | BL9: 0 | BN9: 0.25 | BO9: 0.083333333 | BP9: 0.33333333 | BQ9: -0.33333333 | BR9: -0.33333333 | BS9: -0.33333333 | BT9: -0.33333333 | BU9: 0.083333333 | BV9: -0.33333333 | BW9: 0.16666667 | BX9: 0
B10: Makai | C10: 3 | D10: 9 | E10: 9 | F10: 3 | G10: 3 | H10: 3 | I10: 9 | J10: 3 | K10: 3 | L10: 6 | M10: 0 | N10: 18 | P10: 1 | Q10: 1 | R10: 1 | S10: -2 | T10: -4 | U10: -4 | V10: -4 | W10: 1 | X10: -3 | Y10: 2 | Z10: 0 | AA10: 3 | AC10: 3 | AD10: 1 | AE10: 4 | AF10: -4 | AG10: -4 | AH10: -4 | AI10: -4 | AJ10: 1 | AK10: -4 | AL10: 2 | AM10: 0 | AN10: 5 | AP10: 0.33333333 | AQ10: 1 | AR10: 1 | AS10: 0.33333333 | AT10: 0.33333333 | AU10: 0.33333333 | AV10: 1 | AW10: 0.33333333 | AX10: 0.33333333 | AY10: 0.66666667 | AZ10: 0 | BB10: 0.16666667 | BC10: 0.16666667 | BD10: 0.16666667 | BE10: -0.33333333 | BF10: -0.66666667 | BG10: -0.66666667 | BH10: -0.66666667 | BI10: 0.16666667 | BJ10: -0.5 | BK10: 0.33333333 | BL10: 0 | BN10: 0.25 | BO10: 0.083333333 | BP10: 0.33333333 | BQ10: -0.33333333 | BR10: -0.33333333 | BS10: -0.33333333 | BT10: -0.33333333 | BU10: 0.083333333 | BV10: -0.33333333 | BW10: 0.16666667 | BX10: 0
B11: Makai | C11: 3 | D11: 9 | E11: 9 | F11: 3 | G11: 3 | H11: 3 | I11: 9 | J11: 3 | K11: 3 | L11: 6 | M11: 0 | N11: 18 | P11: 1 | Q11: 1 | R11: 1 | S11: -2 | T11: -4 | U11: -4 | V11: -4 | W11: 1 | X11: -3 | Y11: 2 | Z11: 0 | AA11: 3 | AC11: 3 | AD11: 1 | AE11: 4 | AF11: -4 | AG11: -4 | AH11: -4 | AI11: -4 | AJ11: 1 | AK11: -4 | AL11: 2 | AM11: 0 | AN11: 5 | AP11: 0.33333333 | AQ11: 1 | AR11: 1 | AS11: 0.33333333 | AT11: 0.33333333 | AU11: 0.33333333 | AV11: 1 | AW11: 0.33333333 | AX11: 0.33333333 | AY11: 0.66666667 | AZ11: 0 | BB11: 0.16666667 | BC11: 0.16666667 | BD11: 0.16666667 | BE11: -0.33333333 | BF11: -0.66666667 | BG11: -0.66666667 | BH11: -0.66666667 | BI11: 0.16666667 | BJ11: -0.5 | BK11: 0.33333333 | BL11: 0 | BN11: 0.25 | BO11: 0.083333333 | BP11: 0.33333333 | BQ11: -0.33333333 | BR11: -0.33333333 | BS11: -0.33333333 | BT11: -0.33333333 | BU11: 0.083333333 | BV11: -0.33333333 | BW11: 0.16666667 | BX11: 0
B12: Makai | C12: 3 | D12: 9 | E12: 9 | F12: 3 | G12: 3 | H12: 3 | I12: 9 | J12: 3 | K12: 3 | L12: 6 | M12: 0 | N12: 18 | P12: 1 | Q12: 1 | R12: 1 | S12: -2 | T12: -4 | U12: -4 | V12: -4 | W12: 1 | X12: -3 | Y12: 2 | Z12: 0 | AA12: 3 | AC12: 3 | AD12: 1 | AE12: 4 | AF12: -4 | AG12: -4 | AH12: -4 | AI12: -4 | AJ12: 1 | AK12: -4 | AL12: 2 | AM12: 0 | AN12: 5 | AP12: 0.33333333 | AQ12: 1 | AR12: 1 | AS12: 0.33333333 | AT12: 0.33333333 | AU12: 0.33333333 | AV12: 1 | AW12: 0.33333333 | AX12: 0.33333333 | AY12: 0.66666667 | AZ12: 0 | BB12: 0.16666667 | BC12: 0.16666667 | BD12: 0.16666667 | BE12: -0.33333333 | BF12: -0.66666667 | BG12: -0.66666667 | BH12: -0.66666667 | BI12: 0.16666667 | BJ12: -0.5 | BK12: 0.33333333 | BL12: 0 | BN12: 0.25 | BO12: 0.083333333 | BP12: 0.33333333 | BQ12: -0.33333333 | BR12: -0.33333333 | BS12: -0.33333333 | BT12: -0.33333333 | BU12: 0.083333333 | BV12: -0.33333333 | BW12: 0.16666667 | BX12: 0
B13: Middle | C13: 1 | D13: 3 | E13: 3 | F13: 1 | G13: 1 | H13: 1 | I13: 3 | J13: 1 | K13: 1 | L13: 2 | M13: 0 | N13: 6 | P13: 2 | Q13: 2 | R13: 2 | S13: -4 | T13: -8 | U13: -8 | V13: -8 | W13: 2 | X13: -6 | Y13: 4 | Z13: 0 | AA13: 6 | AC13: 6 | AD13: 2 | AE13: 8 | AF13: -8 | AG13: -8 | AH13: -8 | AI13: -8 | AJ13: 2 | AK13: -8 | AL13: 4 | AM13: 0 | AN13: 10 | AP13: 0.11111111 | AQ13: 0.33333333 | AR13: 0.33333333 | AS13: 0.11111111 | AT13: 0.11111111 | AU13: 0.11111111 | AV13: 0.33333333 | AW13: 0.11111111 | AX13: 0.11111111 | AY13: 0.22222222 | AZ13: 0 | BB13: 0.33333333 | BC13: 0.33333333 | BD13: 0.33333333 | BE13: -0.66666667 | BF13: -1.3333333 | BG13: -1.3333333 | BH13: -1.3333333 | BI13: 0.33333333 | BJ13: -1 | BK13: 0.66666667 | BL13: 0 | BN13: 0.5 | BO13: 0.16666667 | BP13: 0.66666667 | BQ13: -0.66666667 | BR13: -0.66666667 | BS13: -0.66666667 | BT13: -0.66666667 | BU13: 0.16666667 | BV13: -0.66666667 | BW13: 0.33333333 | BX13: 0
B14: Middle | C14: 1 | D14: 3 | E14: 3 | F14: 1 | G14: 1 | H14: 1 | I14: 3 | J14: 1 | K14: 1 | L14: 2 | M14: 0 | N14: 6 | P14: 2 | Q14: 2 | R14: 2 | S14: -4 | T14: -8 | U14: -8 | V14: -8 | W14: 2 | X14: -6 | Y14: 4 | Z14: 0 | AA14: 6 | AC14: 6 | AD14: 2 | AE14: 8 | AF14: -8 | AG14: -8 | AH14: -8 | AI14: -8 | AJ14: 2 | AK14: -8 | AL14: 4 | AM14: 0 | AN14: 10 | AP14: 0.11111111 | AQ14: 0.33333333 | AR14: 0.33333333 | AS14: 0.11111111 | AT14: 0.11111111 | AU14: 0.11111111 | AV14: 0.33333333 | AW14: 0.11111111 | AX14: 0.11111111 | AY14: 0.22222222 | AZ14: 0 | BB14: 0.33333333 | BC14: 0.33333333 | BD14: 0.33333333 | BE14: -0.66666667 | BF14: -1.3333333 | BG14: -1.3333333 | BH14: -1.3333333 | BI14: 0.33333333 | BJ14: -1 | BK14: 0.66666667 | BL14: 0 | BN14: 0.5 | BO14: 0.16666667 | BP14: 0.66666667 | BQ14: -0.66666667 | BR14: -0.66666667 | BS14: -0.66666667 | BT14: -0.66666667 | BU14: 0.16666667 | BV14: -0.66666667 | BW14: 0.33333333 | BX14: 0
... B24: Mauka | C24: 2 | D24: 6 | E24: 6 | F24: 2 | G24: 2 | H24: 2 | I24: 6 | J24: 2 | K24: 2 | L24: 4 | M24: 0 | N24: 12 | P24: 3 | Q24: 3 | R24: 3 | S24: -6 | T24: -12 | U24: -12 | V24: -12 | W24: 3 | X24: -9 | Y24: 6 | Z24: 0 | AA24: 9 | AC24: 9 | AD24: 3 | AE24: 12 | AF24: -12 | AG24: -12 | AH24: -12 | AI24: -12 | AJ24: 3 | AK24: -12 | AL24: 6 | AM24: 0 | AN24: 15 | AP24: 0.22222222 | AQ24: 0.66666667 | AR24: 0.66666667 | AS24: 0.22222222 | AT24: 0.22222222 | AU24: 0.22222222 | AV24: 0.66666667 | AW24: 0.22222222 | AX24: 0.22222222 | AY24: 0.44444444 | AZ24: 0 | BB24: 0.5 | BC24: 0.5 | BD24: 0.5 | BE24: -1 | BF24: -2 | BG24: -2 | BH24: -2 | BI24: 0.5 | BJ24: -1.5 | BK24: 1 | BL24: 0 | BN24: 0.75 | BO24: 0.25 | BP24: 1 | BQ24: -1 | BR24: -1 | BS24: -1 | BT24: -1 | BU24: 0.25 | BV24: -1 | BW24: 0.5 | BX24: 0
M25: 9 | Z25: 6 | AM25: 12 | AZ25: 1 | BL25: 1 | BX25: 1
N26: 294 | P26: -4 | Q26: 2 | AA26: 123 | AN26: 205
P27: -4 | Q27: 2
C28: Community | D28: Hunters | E28: Grazing | H28: Community | I28: Hunters | J28: Grazing | P28: -4 | Q28: 2
B29: Alt_1 | C29: lo | D29: lo | E29: med | G29: Makai | H29: 3 | I29: 1 | J29: 1 | P29: -4 | Q29: 2
B30: Alt_2 | C30: med | D30: lo | E30: lo | G30: middle | H30: 1 | I30: 2 | J30: 2 | K30: Mauka road | L30: 9 | M30: 0 | P30: -4 | Q30: 2 | X30: Mauka road | Y30: 2 | Z30: -4 | AI30: Mauka road | AJ30: 4 | AK30: -4
B31: Alt_3 | C31: med | D31: lo | E31: hi | G31: Mauka | H31: 2 | I31: 3 | J31: 3 | K31: Mauka road | L31: 9 | M31: 0 | P31: -4 | Q31: 2 | X31: Mauka road | Y31: 2 | Z31: -4 | AI31: Mauka road | AJ31: 4 | AK31: -4
B32: Alt_4 | C32: lo | D32: -lo-med | E32: -hi | K32: Mauka road | L32: 9 | M32: 0 | P32: -4 | Q32: 2 | X32: Mauka road | Y32: 2 | Z32: -4 | AI32: Mauka road | AJ32: 4 | AK32: -4
B33: Alt_5 | C33: lo | D33: -hi | E33: -hi | H33: -hi | I33: -4 | K33: Mauka road | L33: 9 | M33: 0 | P33: -4 | Q33: 2 | X33: Mauka road | Y33: 2 | Z33: -4 | AI33: Mauka road | AJ33: 4 | AK33: -4
B34: Alt_6 | C34: lo | D34: -hi | E34: -hi | H34: -med | I34: -3 | K34: Mauka road | L34: 9 | M34: 0 | P34: -4 | Q34: 2 | X34: Mauka road | Y34: 2 | Z34: -4 | AI34: Mauka road | AJ34: 4 | AK34: -4
B35: Alt_7 | C35: med | D35: -hi | E35: -hi | H35: -lo-med | I35: -2 | K35: Mauka road | L35: 9 | M35: 0 | P35: -4 | Q35: 2 | X35: Mauka road | Y35: 2 | Z35: -4 | AI35: Mauka road | AJ35: 4 | AK35: -4
B36: Alt_8 | C36: lo | D36: lo | E36: lo | H36: none | I36: 0 | K36: Mauka road | L36: 9 | M36: 0 | P36: -8 | Q36: 4 | X36: Mauka road | Y36: 2 | Z36: -4 | AI36: Mauka road | AJ36: 4 | AK36: -4
B37: Alt_9 | C37: lo | D37: -med | E37: -hi | H37: lo | I37: 1 | K37: Mauka road | L37: 9 | M37: 0 | P37: -8 | Q37: 4 | X37: Mauka road | Y37: 2 | Z37: -4 | AI37: Mauka road | AJ37: 4 | AK37: -4
B38: Alt_10 | C38: lo-med | D38: lo-med | E38: lo-med | H38: lo-med | I38: 2 | K38: Mauka road | L38: 9 | M38: 0 | P38: -56 | Q38: 28 | X38: Mauka road | Y38: 2 | Z38: -4 | AI38: Mauka road | AJ38: 4 | AK38: -4
B39: Alt_11 | C39: none | D39: none | E39: none | H39: med | I39: 3 | K39: Mauka road | L39: 9 | M39: 0 | X39: Mauka road | Y39: 2 | Z39: -4 | AI39: Mauka road | AJ39: 4 | AK39: -4
H40: hi | I40: 4 | K40: Mauka road | L40: 3 | M40: 0 | X40: Mauka road | Y40: 4 | Z40: -8 | AI40: Mauka road | AJ40: 8 | AK40: -8
K41: Mauka road | L41: 3 | M41: 0 | X41: Mauka road | Y41: 4 | Z41: -8 | AI41: Mauka road | AJ41: 8 | AK41: -8
M42: 0 | Z42: -56 | AK42: -56
M43: 96 | Z43: 28 | AK43: 56

Sheet native_rareplants
H3: RARE PLANTS * Management benefit | T3: RARE PLANTS * Fire reduction benefit | AG3: Rare*Mgmt benefits + Rare*Fire benefits | AT3: Rare*Mgmt benefits + Rare*Fire benefits (SCALED 0-1)
A4: UNIQUE_ID | B4: NATIVE_PCT_COVER | C4: rareplant_count | D4: paddock size | H4: Alt_1 | I4: Alt_2 | J4: Alt_3 | K4: Alt_4 | L4: Alt_5 | M4: Alt_6 | N4: Alt_7 | O4: Alt_8 | P4: Alt_9 | Q4: Alt_10 | R4: Alt_11 | T4: Alt_1 | U4: Alt_2 | V4: Alt_3 | W4: Alt_4 | X4: Alt_5 | Y4: Alt_6 | Z4: Alt_7 | AA4: Alt_8 | AB4: Alt_9 | AC4: Alt_10 | AD4: Alt_11 | AG4: Alt_1 | AH4: Alt_2 | AI4: Alt_3 | AJ4: Alt_4 | AK4: Alt_5 | AL4: Alt_6 | AM4: Alt_7 | AN4: Alt_8 | AO4: Alt_9 | AP4: Alt_10 | AQ4: Alt_11 | AT4: Alt_1 | AU4: Alt_2 | AV4: Alt_3 | AW4: Alt_4 | AX4: Alt_5 | AY4: Alt_6 | AZ4: Alt_7 | BA4: Alt_8 | BB4: Alt_9 | BC4: Alt_10 | BD4: Alt_11
A5: 1 | B5: 0.568207 | C5: 0 | D5: 48.8554 | E5: 0.2775998 | G5: 1 | H5: 0 | I5: 0 | J5: 0 | K5: 0 | L5: 0 | M5: 0 | N5: 0 | O5: 0 | P5: 0 | Q5: 0 | R5: 0 | T5: 0 | U5: 0 | V5: 0 | W5: 0 | X5: 0 | Y5: 0 | Z5: 0 | AA5: 0 | AB5: 0 | AC5: 0 | AD5: 0 | AF5: 1 | AG5: 0 | AH5: 0 | AI5: 0 | AJ5: 0 | AK5: 0 | AL5: 0 | AM5: 0 | AN5: 0 | AO5: 0 | AP5: 0 | AQ5: 0 | AR5: 0 | AT5: 0 | AU5: 0 | AV5: 0 | AW5: 0 | AX5: 0 | AY5: 0 | AZ5: 0 | BA5: 0 | BB5: 0 | BC5: 0 | BD5: 0
A6: 2 | B6: 0.14173 | C6: 3 | D6: 56.4453 | E6: 0.079999924 | G6: 2 | H6: 3 | I6: 3 | J6: -3 | K6: 6 | L6: 9 | M6: 9 | N6: 18 | O6: 3 | P6: 6 | Q6: 3 | R6: 3 | T6: 12.569651 | U6: 6.8278606 | V6: 12.569651 | W6: 12.569651 | X6: 12.569651 | Y6: 12.569651 | Z6: 15 | AA6: 12.569651 | AB6: 12.569651 | AC6: 3 | AD6: 3 | AF6: 2 | AG6: 15.569651 | AH6: 9.8278606 | AI6: 9.5696515 | AJ6: 18.569651 | AK6: 21.569651 | AL6: 21.569651 | AM6: 33 | AN6: 15.569651 | AO6: 18.569651 | AP6: 6 | AQ6: 6 | AR6: 42.827861 | AT6: 0.0030568155 | AU6: 0.0019295202 | AV6: 0.0018788255 | AW6: 0.0036458105 | AX6: 0.0042348055 | AY6: 0.0042348055 | AZ6: 0.0064789447 | BA6: 0.0030568155 | BB6: 0.0036458105 | BC6: 0.00117799 | BD6: 0.00117799
A7: 3 | B7: 1.542957 | C7: 9 | D7: 80.4948 | E7: 1.2420002 | G7: 3 | H7: 9 | I7: 9 | J7: -9 | K7: 18 | L7: 27 | M7: 27 | N7: 54 | O7: 9 | P7: 18 | Q7: 9 | R7: 9 | T7: 26.778715 | U7: 16.111486 | V7: 26.778715 | W7: 26.778715 | X7: 26.778715 | Y7: 26.78864 | Z7: 29.930319 | AA7: 26.78864 | AB7: 26.78864 | AC7: 9 | AD7: 9 | AF7: 3 | AG7: 35.778715 | AH7: 25.111486 | AI7: 17.778715 | AJ7: 44.778715 | AK7: 53.778715 | AL7: 53.78864 | AM7: 83.930319 | AN7: 35.78864 | AO7: 44.78864 | AP7: 18 | AQ7: 18 | AR7: 109.04181 | AT7: 0.0070244945 | AU7: 0.0049301797 | AV7: 0.0034905246 | AW7: 0.0087914794 | AX7: 0.010558464 | AY7: 0.010560413 | AZ7: 0.016478179 | BA7: 0.007026443 | BB7: 0.0087934279 | BC7: 0.0035339699 | BD7: 0.0035339699
A8: 4 | B8: 0.902437 | C8: 8 | D8: 70.4315 | E8: 0.63559992 | G8: 4 | H8: 8 | I8: 8 | J8: -8 | K8: 16 | L8: 24 | M8: 24 | N8: 48 | O8: 8 | P8: 16 | Q8: 8 | R8: 8 | T8: 18.580654 | U8: 12.232262 | V8: 18.580654 | W8: 18.580654 | X8: 18.580654 | Y8: 18.580654 | Z8: 21.08062 | AA8: 18.580654 | AB8: 18.580654 | AC8: 8 | AD8: 8 | AF8: 4 | AG8: 26.580654 | AH8: 20.232262 | AI8: 10.580654 | AJ8: 34.580654 | AK8: 42.580654 | AL8: 42.580654 | AM8: 69.08062 | AN8: 26.580654 | AO8: 34.580654 | AP8: 16 | AQ8: 16 | AR8: 89.312882 | AT8: 0.005218624 | AU8: 0.0039722335 | AV8: 0.0020773175 | AW8: 0.0067892773 | AX8: 0.0083599305 | AY8: 0.0083599304 | AZ8: 0.013562713 | BA8: 0.0052186239 | BB8: 0.0067892772 | BC8: 0.0031413065 | BD8: 0.0031413065
A9: 5 | B9: 1.647397 | C9: 58 | D9: 217.264 | E9: 3.5792006 | G9: 5 | H9: 58 | I9: 58 | J9: -58 | K9: 116 | L9: 174 | M9: 174 | N9: 348 | O9: 58 | P9: 116 | Q9: 58 | R9: 58 | T9: 151.42122 | U9: 95.368486 | V9: 151.42122 | W9: 151.42122 | X9: 151.42122 | Y9: 151.68933 | Z9: 188.52328 | AA9: 151.68933 | AB9: 151.68933 | AC9: 58 | AD9: 58 | AF9: 5 | AG9: 209.42122 | AH9: 153.36849 | AI9: 93.421215 | AJ9: 267.42122 | AK9: 325.42122 | AL9: 325.68933 | AM9: 536.52328 | AN9: 209.68933 | AO9: 267.68933 | AP9: 116 | AQ9: 116 | AR9: 689.89176 | AT9: 0.041116015 | AU9: 0.030111089 | AV9: 0.018341542 | AW9: 0.052503251 | AX9: 0.063890487 | AY9: 0.063943126 | AZ9: 0.10533651 | BA9: 0.041168653 | BB9: 0.05255589 | BC9: 0.022774472 | BD9: 0.022774472
A10: 6 | B10: 0.397277 | C10: 6 | D10: 307.292 | E10: 1.2208004 | G10: 6 | H10: 6 | I10: 6 | J10: -6 | K10: 12 | L10: 18 | M10: 18 | N10: 36 | O10: 6 | P10: 12 | Q10: 6 | R10: 6 | T10: 20.92057 | U10: 11.968228 | V10: 20.92057 | W10: 20.92057 | X10: 20.92057 | Y10: 20.921859 | Z10: 26.493787 | AA10: 20.921859 | AB10: 20.921859 | AC10: 6 | AD10: 6 | AF10: 6 | AG10: 26.92057 | AH10: 17.968228 | AI10: 14.92057 | AJ10: 32.92057 | AK10: 38.92057 | AL10: 38.921859 | AM10: 62.493787 | AN10: 26.921859 | AO10: 32.921859 | AP10: 12 | AQ10: 12 | AR10: 80.462015 | AT10: 0.0052853601 | AU10: 0.003527732 | AV10: 0.0029293802 | AW10: 0.00646335 | AX10: 0.00764134 | AY10: 0.0076415932 | AZ10: 0.012269509 | BA10: 0.0052856133 | BB10: 0.0064636032 | BC10: 0.0023559799 | BD10: 0.0023559799
